Workbook
Name UPDATE: 'Data Sheet'!$E$1

Sheet INPUT SHEET
A3: DESCRIPTION | B3: AXIS BANK LIMITED, FORMERLY KNOWN AS UTI BANK (1993–2007), IS AN INDIAN MULTINATIONAL BANKING AND FINANCIAL SERVICES COMPANY HEADQUARTERED IN MUMBAI. IT IS INDIA'S THIRD LARGEST PRIVATE SECTOR BANK BY ASSETS AND FOURTH LARGEST BY MARKET CAPITALISATION. IT SELLS FINANCIAL SERVICES TO LARGE AND MID-SIZE COMPANIES, SMES AND RETAIL BUSINESSES. | D3: Date | E3: Volume | G3: Price
D4: 46014 | E4: 2.920318 | F4: 1000000 | G4: 1225
D5: 46013 | E5: 2.405809 | G5: 1233.2
D6: 46010 | E6: 5.055047 | G6: 1230.6
D7: 46009 | E7: 3.441592 | G7: 1229.8
D8: 46008 | E8: 5.147181 | G8: 1224.7
D9: 46007 | E9: 11.542048 | G9: 1219.6
D10: 46006 | E10: 1.634472 | G10: 1284.8
D11: 46003 | E11: 2.281078 | G11: 1286.1
D12: 46002 | E12: 2.017404 | G12: 1272.7
D13: 46001 | E13: 2.928746 | G13: 1278.6
D14: 46000 | E14: 4.239279 | G14: 1275.9
D15: 45999 | E15: 2.969478 | G15: 1273.8
D16: 45996 | E16: 2.728214 | G16: 1282.5
... D850: 44768 | E850: 14.135744 | G850: 706.45
D851: 44767 | E851: 6.230411 | G851: 727.35 | U851: 10000000
D852: 44764 | E852: 9.71349 | G852: 730.75 | V852: 100
D853: 44763 | E853: 8.036515 | G853: 715.55 | U853: 1225
D854: 44762 | E854: 11.620331 | G854: 705.7
D855: 44761 | E855: 10.171314 | G855: 700.6
D856: 44760 | E856: 12.464664 | G856: 684.5 | S856: Shareholder's name | T856: N.SHARES(IN CR) | U856: SHAREHOLDINGS(%) | V856: MARKET VALUE (IN CR)
D857: 44757 | E857: 6.015057 | G857: 662.2 | S857: LIFE INSURANCE CORPORATION OF INDIA | T857: 24.486065 | U857: 0.0816 | V857: =U853*$T$857 -> 29995.429
D858: 44756 | E858: 8.026311 | G858: 668.25 | S858: ICICI PRUDENTIAL - THROUGH ITS VARIOUS SCHEMES | T858: 21.130237 | U858: 0.0704 | V858: =U853*T858 -> 25884.541
D859: 44755 | E859: 9.614674 | G859: 679.9 | S859: SBI - THROUGH ITS VARIOUS SCHEMES | T859: 15.797283 | U859: 0.0526 | V859: =U853*T859 -> 19351.672
D860: 44754 | E860: 6.44681 | G860: 676.2 | S860: HDFC - THROUGH ITS VARIOUS SCHEMES | T860: 15.73732 | U860: 0.0524 | V860: =U853*T860 -> 19278.217
D861: 44753 | E861: 14.864285 | G861: 679.85 | S861: NIPPON- THROUGH ITS VARIOUS SCHEMES | T861: 9.6810814 | U861: 0.0323 | V861: =U853*T861 -> 11859.325
D862: 44750 | E862: 12.669533 | G862: 669.15 | S862: NPS TRUST - THROUGH ITS VARIOUS SCHEMES | T862: 7.6208411 | U862: 0.0254 | V862: =U853*T862 -> 9335.5303
D863: 44749 | E863: 11.171714 | G863: 658.15 | S863: DODGE AND COX INTERNATIONAL STOCK FUND | T863: 6.684065 | U863: 0.0223 | V863: =U853*T863 -> 8187.9796
D864: 44748 | E864: 6.684686 | G864: 657.95 | S864: GOVERNMENT PENSION FUND GLOBAL | T864: 6.4578889 | U864: 0.0215 | V864: =U853*T864 -> 7910.9139
D865: 44747 | E865: 5.044787 | G865: 648.5 | S865: GOVERNMENT OF SINGAPORE | T865: 5.7598047 | U865: 0.0192 | V865: =U853*T865 -> 7055.7608
D866: 44746 | E866: 3.933384 | G866: 654.35 | S866: UTI -THROUGH ITS VARIOUS SCHEMES | T866: 5.6237476 | U866: 0.0187 | V866: =U853*T866 -> 6889.0908
D867: 44743 | E867: 6.549359 | G867: 643.95
D868: 44742 | E868: 10.563138 | G868: 636.8
D869: 44741 | E869: 13.620084 | G869: 625.55 | S869: PROMOTER | T869: 0.0816
D870: 44740 | E870: 10.711123 | G870: 642.35 | S870: FII | T870: 0.4189
D871: 44739 | E871: 4.552114 | G871: 637.1 | S871: DII | T871: 0.4282
D872: 44736 | E872: 6.918584 | G872: 634 | S872: PUBLIC | T872: 0.0706
D873: 44735 | E873: 8.450777 | G873: 629.35
D874: 44734 | E874: 5.899024 | G874: 626.8
D875: 44733 | E875: 10.333886 | G875: 636.5
...

Sheet TEASER
B2: AXIS BANK LTD - ONE PAGE PROFILE
C4: ='INPUT SHEET'!B3 -> AXIS BANK LIMITED, FORMERLY KNOWN AS UTI BANK (1993–2007), IS AN INDIAN MULTINATIONAL BANKING AND FINANCIAL SERVICES COMPANY HEADQUARTERED IN MUMBAI. IT IS INDIA'S THIRD LARGEST PRIVATE SECTOR BANK BY ASSETS AND FOURTH LARGEST BY MARKET CAPITALISATION. IT SELLS FINANCIAL SERVICES TO LARGE AND MID-SIZE COMPANIES, SMES AND RETAIL BUSINESSES.
B5: INR (CR)
B6: KEY FINANCIAL METRICS | C6: {='Profit & Loss'!G3:K3} -> 44286 | D6: 44651 | E6: 45016 | F6: 45382 | G6: 45747 | I6: SHARE PRICE-5Y
B8: TOTAL SALES | C8: ='Profit & Loss'!G4 -> 64397.36 | D8: ='Profit & Loss'!H4 -> 68846.06 | E8: ='Profit & Loss'!I4 -> 87448.37 | F8: ='Profit & Loss'!J4 -> 112759.05 | G8: ='Profit & Loss'!K4 -> 127374.09
B9: SALES GROWTH (Y-O-Y) | C9: ='Profit & Loss'!G27 -> 0.010698779 | D9: ='Profit & Loss'!H27 -> 0.069082024 | E9: ='Profit & Loss'!I27 -> 0.27020152 | F9: ='Profit & Loss'!J27 -> 0.2894357 | G9: ='Profit & Loss'!K27 -> 0.12961301
B10: GROSS PROFIT MARGIN (%) | C10: ='Profit & Loss'!G29 -> 0.98065635 | D10: ='Profit & Loss'!H29 -> 0.97893968 | E10: ='Profit & Loss'!I29 -> 0.98175586 | F10: ='Profit & Loss'!J29 -> 0.982802 | G10: ='Profit & Loss'!K29 -> 0.98170986
B11: EBITDA MARGIN (%) | C11: ='Profit & Loss'!G30 -> 0.49344212 | D11: ='Profit & Loss'!H30 -> 0.54657565 | E11: ='Profit & Loss'!I30 -> 0.64960673 | F11: ='Profit & Loss'!J30 -> 0.64494513 | G11: ='Profit & Loss'!K30 -> 0.63575865
B12: EBIT MARGIN (%) | C12: ='Profit & Loss'!G31 -> 0.47828886 | D12: ='Profit & Loss'!H31 -> 0.53138829 | E12: ='Profit & Loss'!I31 -> 0.49928203 | F12: ='Profit & Loss'!J31 -> 0.63266257 | G12: ='Profit & Loss'!K31 -> 0.62191377
B13: NET MARGIN PROFIT (%) | C13: ='Profit & Loss'!G32 -> 0.11173595 | D13: ='Profit & Loss'!H32 -> 0.20508494 | E13: ='Profit & Loss'!I32 -> 0.12371243 | F13: ='Profit & Loss'!J32 -> 0.23400516 | G13: ='Profit & Loss'!K32 -> 0.22025759
B14: EARNINGS PER SHARE (IN RS) | C14: ='Profit & Loss'!G13 -> 23.486307 | D14: ='Profit & Loss'!H13 -> 45.995667 | E14: ='Profit & Loss'!I13 -> 35.160226 | F14: ='Profit & Loss'!J13 -> 85.486296 | G14: ='Profit & Loss'!K13 -> 90.576322
B15: EPS GROWTH (Y-O-Y%) | C15: ='Profit & Loss'!G33 -> 2.5762213 | D15: ='Profit & Loss'!H33 -> 0.95840353 | E15: ='Profit & Loss'!I33 -> -0.23557526 | F15: ='Profit & Loss'!J33 -> 1.4313352 | G15: ='Profit & Loss'!K33 -> 0.059542017
B16: DIVIDEND PER SHARE | C16: ='Profit & Loss'!G34 -> 0 | D16: ='Profit & Loss'!H34 -> 1.0000326 | E16: ='Profit & Loss'!I34 -> 0.9999675 | F16: ='Profit & Loss'!J34 -> 1 | G16: ='Profit & Loss'!K34 -> 1
B17: DPS GROWTH (%) | C17: =0 -> 0 | D17: ='Profit & Loss'!H35 -> -1 | E17: ='Profit & Loss'!I35 -> 6.5078832e-05 | F17: ='Profit & Loss'!J35 -> -3.2500244e-05 | G17: ='Profit & Loss'!K35 -> 0
B19: KEY FINANCIAL RATIOS | C19: =C6 -> 44286 | D19: =D6 -> 44651 | E19: =E6 -> 45016 | F19: =F6 -> 45382 | G19: =G6 -> 45747 | I19: VOLUME-5Y
B21: PRICE TO EARNINGS | C21: ='Profit & Loss'!G14 -> 29.696026 | D21: ='Profit & Loss'!H14 -> 16.548298 | E21: ='Profit & Loss'!I14 -> 24.416794 | F21: ='Profit & Loss'!J14 -> 12.249917 | G21: ='Profit & Loss'!K14 -> 12.166535
B22: EV/EBITDA | C22: ='Profit & Loss'!G42 -> 46.255891 | D22: ='Profit & Loss'!H42 -> 40.953512 | E22: ='Profit & Loss'!I42 -> 3.6562361 | F22: ='Profit & Loss'!J42 -> 3.3934892 | G22: ='Profit & Loss'!K42 -> 3.4054306
B23: EV/SALES | C23: ='Profit & Loss'!G43 -> 22.824605 | D23: ='Profit & Loss'!H43 -> 22.384192 | E23: ='Profit & Loss'!I43 -> 2.3751156 | F23: ='Profit & Loss'!J43 -> 2.1886143 | G23: ='Profit & Loss'!K43 -> 2.165032
B24: PRICE TO BOOK VALUE | C24: ='Profit & Loss'!G44 -> 2.062652 | D24: ='Profit & Loss'!H44 -> 1.9757222 | E24: ='Profit & Loss'!I44 -> 2.0353551 | F24: ='Profit & Loss'!J44 -> 2.0584735 | G24: ='Profit & Loss'!K44 -> 1.823017
B25: RETURN ON EQUITY(%) | C25: ='Balance Sheet'!G23 -> 0.069458857 | D25: ='Balance Sheet'!H23 -> 0.11939127 | E25: ='Balance Sheet'!I23 -> 0.083358818 | F25: ='Balance Sheet'!J23 -> 0.16803979 | G25: ='Balance Sheet'!K23 -> 0.14983863
B26: RETURN ON CAPITAL EMPLOYED(%) | C26: ='Balance Sheet'!G24 -> 0.048293512 | D26: ='Balance Sheet'!H24 -> 0.051450693 | E26: ='Balance Sheet'!I24 -> 0.051226539 | F26: ='Balance Sheet'!J24 -> 0.070639065 | G26: ='Balance Sheet'!K24 -> 0.071100281
B28: TOP 10 SHAREHOLDERS | C28: NO.OF SHARES(IN CR) | E28: % HOLDINGS | F28: MARKET VALUE (IN CR) | I28: SHAREHOLDING PATTERN
B30: ='INPUT SHEET'!S857 -> LIFE INSURANCE CORPORATION OF INDIA | C30: ='INPUT SHEET'!T857 -> 24.486065 | E30: ='INPUT SHEET'!U857 -> 0.0816 | F30: ='INPUT SHEET'!V857 -> 29995.429
B31: ='INPUT SHEET'!S858 -> ICICI PRUDENTIAL - THROUGH ITS VARIOUS SCHEMES | C31: ='INPUT SHEET'!T858 -> 21.130237 | E31: ='INPUT SHEET'!U858 -> 0.0704 | F31: ='INPUT SHEET'!V858 -> 25884.541
B32: ='INPUT SHEET'!S859 -> SBI - THROUGH ITS VARIOUS SCHEMES | C32: ='INPUT SHEET'!T859 -> 15.797283 | E32: ='INPUT SHEET'!U859 -> 0.0526 | F32: ='INPUT SHEET'!V859 -> 19351.672
B33: ='INPUT SHEET'!S860 -> HDFC - THROUGH ITS VARIOUS SCHEMES | C33: ='INPUT SHEET'!T860 -> 15.73732 | E33: ='INPUT SHEET'!U860 -> 0.0524 | F33: ='INPUT SHEET'!V860 -> 19278.217
B34: ='INPUT SHEET'!S861 -> NIPPON- THROUGH ITS VARIOUS SCHEMES | C34: ='INPUT SHEET'!T861 -> 9.6810814 | E34: ='INPUT SHEET'!U861 -> 0.0323 | F34: ='INPUT SHEET'!V861 -> 11859.325
B35: ='INPUT SHEET'!S862 -> NPS TRUST - THROUGH ITS VARIOUS SCHEMES | C35: ='INPUT SHEET'!T862 -> 7.6208411 | E35: ='INPUT SHEET'!U862 -> 0.0254 | F35: ='INPUT SHEET'!V862 -> 9335.5303
B36: ='INPUT SHEET'!S863 -> DODGE AND COX INTERNATIONAL STOCK FUND | C36: ='INPUT SHEET'!T863 -> 6.684065 | E36: ='INPUT SHEET'!U863 -> 0.0223 | F36: ='INPUT SHEET'!V863 -> 8187.9796
B37: ='INPUT SHEET'!S864 -> GOVERNMENT PENSION FUND GLOBAL | C37: ='INPUT SHEET'!T864 -> 6.4578889 | E37: ='INPUT SHEET'!U864 -> 0.0215 | F37: ='INPUT SHEET'!V864 -> 7910.9139
B38: ='INPUT SHEET'!S865 -> GOVERNMENT OF SINGAPORE | C38: ='INPUT SHEET'!T865 -> 5.7598047 | E38: ='INPUT SHEET'!U865 -> 0.0192 | F38: ='INPUT SHEET'!V865 -> 7055.7608
B39: ='INPUT SHEET'!S866 -> UTI -THROUGH ITS VARIOUS SCHEMES | C39: ='INPUT SHEET'!T866 -> 5.6237476 | E39: ='INPUT SHEET'!U866 -> 0.0187 | F39: ='INPUT SHEET'!V866 -> 6889.0908
B41: MANAGERIAL REMUNERATION | C41: DESIGNATION | D41: REMUNERATION (IN CR) | F41: X OF MEDIAN SALARY | I41: CAPITAL STRUCTURE
B43: AMITABH CHOUDHRY | C43: MD & CEO | D43: 9.8 | F43: 101.8 | I43: SHARE PRICE AS ON 25-12-2025 | K43: ='Data Sheet'!B8 -> 1226
B44: RAJIV ANAND | C44: DEPUTY MD | D44: 6.84 | F44: 66.5 | I44: NUMBER OF SHARES O/S | K44: ='Data Sheet'!B6 -> 312.26
B45: SUBRAT MOHANTY | C45: EXC.DIRECTOR | D45: 5.44 | F45: 54 | I45: MARKET CAPITALIZATION | K45: =K43*K44 -> 382830.76
B46: MUNISH SHARDA | C46: EXC.DIRECTOR | D46: 5.63 | F46: 54 | I46: LESS:CASH &EQUIVALENTS | K46: ='Data Sheet'!K69*-1 -> -65564.5
B47: PUNEET SHARMA | C47: CFO | D47: 2.49 | F47: 32.9 | I47: ADD:TOTAL DEBT | K47: ='Data Sheet'!K59 -> 1391607.6
B48: SANDEEP PODDAR | C48: C.S | D48: 1.35 | F48: 17.9 | I48: ADD:MINORITY INTEREST | K48: 635.13
I49: ENTERPRISE VALUE | K49: =SUM(K45:K48) -> 1709509
...

Sheet Profit & Loss
A1: ='Data Sheet'!B1 -> AXIS BANK LTD | H1: =UPDATE | M1: SCREENER.IN
A3: Narration | B3: ='Data Sheet'!B16 -> 42460 | C3: ='Data Sheet'!C16 -> 42825 | D3: ='Data Sheet'!D16 -> 43190 | E3: ='Data Sheet'!E16 -> 43555 | F3: ='Data Sheet'!F16 -> 43921 | G3: ='Data Sheet'!G16 -> 44286 | H3: ='Data Sheet'!H16 -> 44651 | I3: ='Data Sheet'!I16 -> 45016 | ... K3: ='Data Sheet'!K16 -> 45747 | L3: Trailing | M3: Best Case | N3: Worst Case
A4: Sales | B4: ='Data Sheet'!B17 -> 41409.25 | C4: ='Data Sheet'!C17 -> 45175.09 | D4: ='Data Sheet'!D17 -> 46614.06 | E4: ='Data Sheet'!E17 -> 56043.65 | F4: ='Data Sheet'!F17 -> 63715.68 | G4: ='Data Sheet'!G17 -> 64397.36 | H4: ='Data Sheet'!H17 -> 68846.06 | I4: ='Data Sheet'!I17 -> 87448.37 | ... K4: ='Data Sheet'!K17 -> 127374.09 | L4: =SUM(Quarters!H4:K4) -> 129272.6 | M4: =$K4+M23*K4 -> 156368.2 | N4: =$K4+N23*L4 -> 144129.5
A5: Expenses | B5: =SUM('Data Sheet'!B18,'Data Sheet'!B20:B24, -1*'Data Sheet'!B19) -> 13868.65 | C5: =SUM('Data Sheet'!C18,'Data Sheet'!C20:C24, -1*'Data Sheet'!C19) -> 24326.86 | D5: =SUM('Data Sheet'!D18,'Data Sheet'!D20:D24, -1*'Data Sheet'!D19) -> 29716.53 | E5: =SUM('Data Sheet'!E18,'Data Sheet'!E20:E24, -1*'Data Sheet'!E19) -> 28019.71 | F5: =SUM('Data Sheet'!F18,'Data Sheet'!F20:F24, -1*'Data Sheet'!F19) -> 35975.61 | G5: =SUM('Data Sheet'!G18,'Data Sheet'!G20:G24, -1*'Data Sheet'!G19) -> 32620.99 | H5: =SUM('Data Sheet'!H18,'Data Sheet'!H20:H24, -1*'Data Sheet'!H19) -> 31216.48 | I5: =SUM('Data Sheet'!I18,'Data Sheet'!I20:I24, -1*'Data Sheet'!I19) -> 30641.32 | ... K5: =SUM('Data Sheet'!K18,'Data Sheet'!K20:K24, -1*'Data Sheet'!K19) -> 46394.91 | L5: =SUM(Quarters!H5:K5) -> 52140.34 | M5: =M4-M6 -> 55883.248 | N5: =N4-N6 -> 63165.048
A6: Operating Profit | B6: =B4-B5 -> 27540.6 | C6: =C4-C5 -> 20848.23 | D6: =D4-D5 -> 16897.53 | E6: =E4-E5 -> 28023.94 | F6: =F4-F5 -> 27740.07 | G6: =G4-G5 -> 31776.37 | H6: =H4-H5 -> 37629.58 | I6: =I4-I5 -> 56807.05 | ... K6: =K4-K5 -> 80979.18 | L6: =SUM(Quarters!H6:K6) -> 77132.26 | M6: =M4*M24 -> 100484.95 | N6: =N4*N24 -> 80964.452
A7: Other Income | B7: ='Data Sheet'!B25 -> 9954.98 | C7: ='Data Sheet'!C25 -> 12421.6 | D7: ='Data Sheet'!D25 -> 11862.62 | E7: ='Data Sheet'!E25 -> 14188.75 | F7: ='Data Sheet'!F25 -> 16341.99 | G7: ='Data Sheet'!G25 -> 13576.92 | H7: ='Data Sheet'!H25 -> 17268.13 | I7: ='Data Sheet'!I25 -> 18348.93 | ... K7: ='Data Sheet'!K25 -> 28542.77 | L7: =SUM(Quarters!H7:K7) -> 29815.46 | M7: 0 | N7: 0
A8: Depreciation | B8: ='Data Sheet'!B26 -> 461.39 | C8: ='Data Sheet'!C26 -> 526.67 | D8: ='Data Sheet'!D26 -> 590.58 | E8: ='Data Sheet'!E26 -> 737.17 | F8: ='Data Sheet'!F26 -> 806.07 | G8: ='Data Sheet'!G26 -> 975.83 | H8: ='Data Sheet'!H26 -> 1045.59 | I8: ='Data Sheet'!I26 -> 13145.65 | ... K8: ='Data Sheet'!K26 -> 1763.48 | L8: =SUM(Quarters!H8:K8) -> 0 | M8: =+$L8 -> 0 | N8: =+$L8 -> 0
A9: Interest | B9: ='Data Sheet'!B27 -> 24344.23 | C9: ='Data Sheet'!C27 -> 26789.35 | D9: ='Data Sheet'!D27 -> 27603.69 | E9: ='Data Sheet'!E27 -> 33883.47 | F9: ='Data Sheet'!F27 -> 37995.94 | G9: ='Data Sheet'!G27 -> 34627.38 | H9: ='Data Sheet'!H27 -> 34922.66 | I9: ='Data Sheet'!I27 -> 43389.15 | ... K9: ='Data Sheet'!K27 -> 71036.31 | L9: =SUM(Quarters!H9:K9) -> 72370.55 | M9: =+$L9 -> 72370.55 | N9: =+$L9 -> 72370.55
A10: Profit before tax | B10: ='Data Sheet'!B28 -> 12689.96 | C10: ='Data Sheet'!C28 -> 5953.81 | D10: ='Data Sheet'!D28 -> 565.88 | E10: ='Data Sheet'!E28 -> 7592.05 | F10: ='Data Sheet'!F28 -> 5280.05 | G10: ='Data Sheet'!G28 -> 9750.08 | H10: ='Data Sheet'!H28 -> 18929.46 | I10: ='Data Sheet'!I28 -> 18621.18 | ... K10: ='Data Sheet'!K28 -> 36722.16 | L10: =SUM(Quarters!H10:K10) -> 34577.17 | M10: =M6+M7-SUM(M8:M9) -> 28114.399 | N10: =N6+N7-SUM(N8:N9) -> 8593.9025
A11: Tax | B11: ='Data Sheet'!B29 -> 4332.38 | C11: ='Data Sheet'!C29 -> 1986.78 | D11: ='Data Sheet'!D29 -> 101.86 | E11: ='Data Sheet'!E29 -> 2544.96 | F11: ='Data Sheet'!F29 -> 3401.29 | G11: ='Data Sheet'!G29 -> 2497.69 | H11: ='Data Sheet'!H29 -> 4765.11 | I11: ='Data Sheet'!I29 -> 7768.52 | ... K11: ='Data Sheet'!K29 -> 8610.42 | L11: =SUM(Quarters!H11:K11) -> 8506.68 | M11: =IF($L10>0,$L11/$L10,0) -> 0.24602013 | N11: =IF($L10>0,$L11/$L10,0) -> 0.24602013
A12: Net profit | B12: ='Data Sheet'!B30 -> 8349.67 | C12: ='Data Sheet'!C30 -> 3953.03 | D12: ='Data Sheet'!D30 -> 455.82 | E12: ='Data Sheet'!E30 -> 5038.59 | F12: ='Data Sheet'!F30 -> 1853.11 | G12: ='Data Sheet'!G30 -> 7195.5 | H12: ='Data Sheet'!H30 -> 14119.29 | I12: ='Data Sheet'!I30 -> 10818.45 | ... K12: ='Data Sheet'!K30 -> 28055.11 | L12: =SUM(Quarters!H12:K12) -> 25988.99 | M12: =M10-M11*M10 -> 21197.691 | N12: =N10-N11*N10 -> 6479.6295
A13: EPS | B13: =IF('Data Sheet'!B93>0,B12/'Data Sheet'!B93,0) -> 35.041422 | C13: =IF('Data Sheet'!C93>0,C12/'Data Sheet'!C93,0) -> 16.505344 | D13: =IF('Data Sheet'!D93>0,D12/'Data Sheet'!D93,0) -> 1.7760374 | E13: =IF('Data Sheet'!E93>0,E12/'Data Sheet'!E93,0) -> 19.59321 | F13: =IF('Data Sheet'!F93>0,F12/'Data Sheet'!F93,0) -> 6.567353 | G13: =IF('Data Sheet'!G93>0,G12/'Data Sheet'!G93,0) -> 23.486307 | H13: =IF('Data Sheet'!H93>0,H12/'Data Sheet'!H93,0) -> 45.995667 | I13: =IF('Data Sheet'!I93>0,I12/'Data Sheet'!I93,0) -> 35.160226 | ... K13: =IF('Data Sheet'!K93>0,K12/'Data Sheet'!K93,0) -> 90.576322 | L13: =IF('Data Sheet'!$B6>0,'Profit & Loss'!L12/'Data Sheet'!$B6,0) -> 83.228688 | M13: =IF('Data Sheet'!$B6>0,'Profit & Loss'!M12/'Data Sheet'!$B6,0) -> 67.884746 | N13: =IF('Data Sheet'!$B6>0,'Profit & Loss'!N12/'Data Sheet'!$B6,0) -> 20.750751
A14: Price to earning | B14: =IF(B15>0,B15/B13,"") -> 12.674999 | C14: =IF(C15>0,C15/C13,"") -> 29.735823 | D14: =IF(D15>0,D15/D13,"") -> 287.43764 | E14: =IF(E15>0,E15/E13,"") -> 39.669354 | F14: =IF(F15>0,F15/F13,"") -> 57.709704 | G14: =IF(G15>0,G15/G13,"") -> 29.696026 | H14: =IF(H15>0,H15/H13,"") -> 16.548298 | I14: =IF(I15>0,I15/I13,"") -> 24.416794 | ... K14: =IF(K15>0,K15/K13,"") -> 12.166535 | L14: =IF(L13>0,L15/L13,0) -> 14.730498 | M14: =M25 -> 15.890936 | N14: =N25 -> 14.730498
A15: Price | B15: ='Data Sheet'!B90 -> 444.15 | C15: ='Data Sheet'!C90 -> 490.8 | D15: ='Data Sheet'!D90 -> 510.5 | E15: ='Data Sheet'!E90 -> 777.25 | F15: ='Data Sheet'!F90 -> 379 | G15: ='Data Sheet'!G90 -> 697.45 | H15: ='Data Sheet'!H90 -> 761.15 | I15: ='Data Sheet'!I90 -> 858.5 | ... K15: ='Data Sheet'!K90 -> 1102 | L15: ='Data Sheet'!B8 -> 1226 | M15: =M13*M14 -> 1078.7521 | N15: =N13*N14 -> 305.66889
A17: RATIOS:
A18: Dividend Payout | B18: =IF('Data Sheet'!B30>0, 'Data Sheet'!B31/'Data Sheet'!B30, 0) -> 0.14269067 | C18: =IF('Data Sheet'!C30>0, 'Data Sheet'!C31/'Data Sheet'!C30, 0) -> 0.30293724 | D18: =IF('Data Sheet'!D30>0, 'Data Sheet'!D31/'Data Sheet'!D30, 0) -> 0 | E18: =IF('Data Sheet'!E30>0, 'Data Sheet'!E31/'Data Sheet'!E30, 0) -> 0.051038088 | F18: =IF('Data Sheet'!F30>0, 'Data Sheet'!F31/'Data Sheet'!F30, 0) -> 0 | G18: =IF('Data Sheet'!G30>0, 'Data Sheet'!G31/'Data Sheet'!G30, 0) -> 0 | H18: =IF('Data Sheet'!H30>0, 'Data Sheet'!H31/'Data Sheet'!H30, 0) -> 0.021741886 | I18: =IF('Data Sheet'!I30>0, 'Data Sheet'!I31/'Data Sheet'!I30, 0) -> 0.028440303 | ... K18: =IF('Data Sheet'!K30>0, 'Data Sheet'!K31/'Data Sheet'!K30, 0) -> 0.011040413
A19: OPM | B19: =IF(B6>0,B6/B4,0) -> 0.66508328 | C19: =IF(C6>0,C6/C4,0) -> 0.46149836 | D19: =IF(D6>0,D6/D4,0) -> 0.36249857 | E19: =IF(E6>0,E6/E4,0) -> 0.50003774 | F19: =IF(F6>0,F6/F4,0) -> 0.43537274 | G19: =IF(G6>0,G6/G4,0) -> 0.49344212 | H19: =IF(H6>0,H6/H4,0) -> 0.54657565 | I19: =IF(I6>0,I6/I4,0) -> 0.64960673 | ... L19: =IF(L6>0,L6/L4,0) -> 0.59666364
G22: TRENDS: | H22: 10 YEARS | I22: 7 YEARS | J22: 5 YEARS | K22: 3 YEARS | L22: RECENT | M22: BEST | N22: WORST
G23: Sales Growth | H23: =IF(B4=0,"",POWER($K4/B4,1/9)-1) -> 0.13297523 | I23: =IF(D4=0,"",POWER($K4/D4,1/7)-1) -> 0.15442656 | J23: =IF(F4=0,"",POWER($K4/F4,1/5)-1) -> 0.14859509 | K23: =IF(H4=0,"",POWER($K4/H4, 1/3)-1) -> 0.22762955 | L23: =IF(ISERROR(MAX(IF(J4=0,"",(K4-J4)/J4),IF(K4=0,"",(L4-K4)/K4))),"",MAX(IF(J4=0,"",(K4-J4)/J4),IF(K4=0,"",(L4-K4)/K4))) -> 0.12961301 | M23: =MAX(K23:L23) -> 0.22762955 | N23: =MIN(H23:L23) -> 0.12961301
G24: OPM | H24: =IF(SUM(B4:$K$4)=0,"",SUMPRODUCT(B19:$K$19,B4:$K$4)/SUM(B4:$K$4)) -> 0.56174796 | I24: =IF(SUM(E4:$K$4)=0,"",SUMPRODUCT(E19:$K$19,E4:$K$4)/SUM(E4:$K$4)) -> 0.57817549 | J24: =IF(SUM(G4:$K$4)=0,"",SUMPRODUCT(G19:$K$19,G4:$K$4)/SUM(G4:$K$4)) -> 0.60742282 | K24: =IF(SUM(I4:$K$4)=0, "", SUMPRODUCT(I19:$K$19,I4:$K$4)/SUM(I4:$K$4)) -> 0.64261756 | L24: =L19 -> 0.59666364 | M24: =MAX(K24:L24) -> 0.64261756 | N24: =MIN(H24:L24) -> 0.56174796
G25: Price to Earning | H25: =IF(ISERROR(AVERAGEIF(B14:$L14,">0")),"",AVERAGEIF(B14:$L14,">0")) -> 48.821417 | I25: =IF(ISERROR(AVERAGEIF(E14:$L14,">0")),"",AVERAGEIF(E14:$L14,">0")) -> 25.898391 | J25: =IF(ISERROR(AVERAGEIF(G14:$L14,">0")),"",AVERAGEIF(G14:$L14,">0")) -> 18.301345 | K25: =IF(ISERROR(AVERAGEIF(I14:$L14,">0")),"",AVERAGEIF(I14:$L14,">0")) -> 15.890936 | L25: =L14 -> 14.730498 | M25: =MAX(K25:L25) -> 15.890936 | N25: =MIN(H25:L25) -> 14.730498
A27: SALES GROWTH Y-O-Y | C27: =C4/B4-1 -> 0.090942 | D27: =D4/C4-1 -> 0.031853174 | E27: =E4/D4-1 -> 0.20229068 | F27: =F4/E4-1 -> 0.13689383 | G27: =G4/F4-1 -> 0.010698779 | H27: =H4/G4-1 -> 0.069082024 | I27: =I4/H4-1 -> 0.27020152 | J27: =J4/I4-1 -> 0.2894357 | K27: =K4/J4-1 -> 0.12961301
A28: GROSS PROFIT | B28: ='Data Sheet'!B17-'Data Sheet'!B18-'Data Sheet'!B19-'Data Sheet'!B20-'Data Sheet'!B21 -> 40673.12 | C28: ='Data Sheet'!C17-'Data Sheet'!C18-'Data Sheet'!C19-'Data Sheet'!C20-'Data Sheet'!C21 -> 44294.56 | D28: ='Data Sheet'!D17-'Data Sheet'!D18-'Data Sheet'!D19-'Data Sheet'!D20-'Data Sheet'!D21 -> 45736 | E28: ='Data Sheet'!E17-'Data Sheet'!E18-'Data Sheet'!E19-'Data Sheet'!E20-'Data Sheet'!E21 -> 54950.43 | F28: ='Data Sheet'!F17-'Data Sheet'!F18-'Data Sheet'!F19-'Data Sheet'!F20-'Data Sheet'!F21 -> 62529.64 | G28: ='Data Sheet'!G17-'Data Sheet'!G18-'Data Sheet'!G19-'Data Sheet'!G20-'Data Sheet'!G21 -> 63151.68 | H28: ='Data Sheet'!H17-'Data Sheet'!H18-'Data Sheet'!H19-'Data Sheet'!H20-'Data Sheet'!H21 -> 67396.14 | I28: ='Data Sheet'!I17-'Data Sheet'!I18-'Data Sheet'!I19-'Data Sheet'!I20-'Data Sheet'!I21 -> 85852.95 | ... K28: ='Data Sheet'!K17-'Data Sheet'!K18-'Data Sheet'!K19-'Data Sheet'!K20-'Data Sheet'!K21 -> 125044.4
A29: GPM | B29: =B28/B4 -> 0.98222305 | C29: =C28/C4 -> 0.98050851 | D29: =D28/D4 -> 0.98116319 | E29: =E28/E4 -> 0.98049342 | F29: =F28/F4 -> 0.98138543 | G29: =G28/G4 -> 0.98065635 | H29: =H28/H4 -> 0.97893968 | I29: =I28/I4 -> 0.98175586 | ... K29: =K28/K4 -> 0.98170986
A30: EBITDA MARGIN | B30: =B6/B4 -> 0.66508328 | C30: =C6/C4 -> 0.46149836 | D30: =D6/D4 -> 0.36249857 | E30: =E6/E4 -> 0.50003774 | F30: =F6/F4 -> 0.43537274 | G30: =G6/G4 -> 0.49344212 | H30: =H6/H4 -> 0.54657565 | I30: =I6/I4 -> 0.64960673 | ... K30: =K6/K4 -> 0.63575865
A31: EBIT MARGIN | B31: =(B6-B8)/B4 -> 0.65394109 | C31: =(C6-C8)/C4 -> 0.44983994 | D31: =(D6-D8)/D4 -> 0.349829 | E31: =(E6-E8)/E4 -> 0.48688424 | F31: =(F6-F8)/F4 -> 0.42272169 | G31: =(G6-G8)/G4 -> 0.47828886 | H31: =(H6-H8)/H4 -> 0.53138829 | I31: =(I6-I8)/I4 -> 0.49928203 | ... K31: =(K6-K8)/K4 -> 0.62191377
A32: NET PROFIT MARGIN | B32: =B12/B4 -> 0.2016378 | C32: =C12/C4 -> 0.08750464 | D32: =D12/D4 -> 0.0097785947 | E32: =E12/E4 -> 0.089904744 | F32: =F12/F4 -> 0.02908405 | G32: =G12/G4 -> 0.11173595 | H32: =H12/H4 -> 0.20508494 | I32: =I12/I4 -> 0.12371243 | ... K32: =K12/K4 -> 0.22025759
A33: EPS GROWTH | C33: =C13/B13-1 -> -0.52897618 | D33: =D13/C13-1 -> -0.89239622 | E33: =E13/D13-1 -> 10.031981 | F33: =F13/E13-1 -> -0.66481486 | G33: =G13/F13-1 -> 2.5762213 | H33: =H13/G13-1 -> 0.95840353 | I33: =I13/H13-1 -> -0.23557526 | J33: =J13/I13-1 -> 1.4313352 | K33: =K13/J13-1 -> 0.059542017
A34: DIVIDEND PER SHARE | B34: =B13*B18 -> 5.0000839 | C34: =C13*C18 -> 5.0000835 | D34: =D13*D18 -> 0 | E34: =E13*E18 -> 1 | F34: =F13*F18 -> 0 | G34: =G13*G18 -> 0 | H34: =H13*H18 -> 1.0000326 | I34: =I13*I18 -> 0.9999675 | ... K34: =K13*K18 -> 1
A35: DIVIDEND GROWTH | C35: =B34/C34-1 -> 8.5510503e-08 | D35: =C34/D34-1 -> #DIV/0! | E35: =D34/E34-1 -> -1 | F35: =E34/F34-1 -> #DIV/0! | G35: =F34/G34-1 -> #DIV/0! | H35: =G34/H34-1 -> -1 | I35: =H34/I34-1 -> 6.5078832e-05 | J35: =I34/J34-1 -> -3.2500244e-05 | K35: =J34/K34-1 -> 0
A37: MARKET CAPITALIZATION | B37: ='Data Sheet'!B93*'Data Sheet'!B90 -> 105832.06 | C37: ='Data Sheet'!C93*'Data Sheet'!C90 -> 117546.6 | D37: ='Data Sheet'!D93*'Data Sheet'!D90 -> 131019.82 | E37: ='Data Sheet'!E93*'Data Sheet'!E90 -> 199877.61 | F37: ='Data Sheet'!F93*'Data Sheet'!F90 -> 106942.43 | G37: ='Data Sheet'!G93*'Data Sheet'!G90 -> 213677.76 | H37: ='Data Sheet'!H93*'Data Sheet'!H90 -> 233650.22 | I37: ='Data Sheet'!I93*'Data Sheet'!I90 -> 264151.86 | ... K37: ='Data Sheet'!K93*'Data Sheet'!K90 -> 341333.48
A38: DEBT | B38: ='Balance Sheet'!E6 -> 711995.77 | C38: ='Balance Sheet'!F6 -> 797337.38 | D38: ='Balance Sheet'!G6 -> 850551.35 | E38: ='Balance Sheet'!H6 -> 1020943 | F38: ='Balance Sheet'!I6 -> 1152038.3 | G38: ='Balance Sheet'!J6 -> 1295301.9 | H38: ='Balance Sheet'!K6 -> 1391607.6 | I38: ='Balance Sheet'!L6 -> 0 | ... K38: ='Balance Sheet'!N6 -> 0
A39: CASH | B39: ='Data Sheet'!B69 -> 18240.67 | C39: ='Data Sheet'!C69 -> 24500.02 | D39: ='Data Sheet'!D69 -> 30223.02 | E39: ='Data Sheet'!E69 -> 30885.82 | F39: ='Data Sheet'!F69 -> 76971.34 | G39: ='Data Sheet'!G69 -> 39135.41 | H39: ='Data Sheet'!H69 -> 84194.41 | I39: ='Data Sheet'!I69 -> 56451.88 | ... K39: ='Data Sheet'!K69 -> 65564.5
A40: EV | B40: =B37+B38-B39 -> 799587.16 | C40: =C37+C38-C39 -> 890383.96 | D40: =D37+D38-D39 -> 951348.15 | E40: =E37+E38-E39 -> 1189934.8 | F40: =F37+F38-F39 -> 1182009.4 | G40: =G37+G38-G39 -> 1469844.3 | H40: =H37+H38-H39 -> 1541063.4 | I40: =I37+I38-I39 -> 207699.98 | ... K40: =K37+K38-K39 -> 275768.98
A42: EV /EBITDA | B42: =B40/B6 -> 29.033033 | C42: =C40/C6 -> 42.707892 | D42: =D40/D6 -> 56.301019 | E42: =E40/E6 -> 42.461365 | F42: =F40/F6 -> 42.61018 | G42: =G40/G6 -> 46.255891 | H42: =H40/H6 -> 40.953512 | I42: =I40/I6 -> 3.6562361 | ... K42: =K40/K6 -> 3.4054306
A43: EV/SALES | B43: =B40/B4 -> 19.309385 | C43: =C40/C4 -> 19.709622 | D43: =D40/D4 -> 20.409039 | E43: =E40/E4 -> 21.232285 | F43: =F40/F4 -> 18.551311 | G43: =G40/G4 -> 22.824605 | H43: =H40/H4 -> 22.384192 | I43: =I40/I4 -> 2.3751156 | ... K43: =K40/K4 -> 2.165032
A44: P/B | B44: =B37/'Balance Sheet'!B26 -> 1.9759991 | C44: =C37/'Balance Sheet'!C26 -> 2.084886 | D44: =D37/'Balance Sheet'!D26 -> 2.0405717 | E44: =E37/'Balance Sheet'!E26 -> 2.9479334 | F44: =F37/'Balance Sheet'!F26 -> 1.2386136 | G44: =G37/'Balance Sheet'!G26 -> 2.062652 | H44: =H37/'Balance Sheet'!H26 -> 1.9757222 | I44: =I37/'Balance Sheet'!I26 -> 2.0353551 | ... K44: =K37/'Balance Sheet'!K26 -> 1.823017
A46: retained earning | E46: =IFERROR(IF(E13>E34,1-E18,0),0) -> 0.94896191 | F46: =IFERROR(IF(F13>F34,1-F18,0),0) -> 1 | G46: =IFERROR(IF(G13>G34,1-G18,0),0) -> 1 | H46: =IFERROR(IF(H13>H34,1-H18,0),0) -> 0.97825811 | I46: =IFERROR(IF(I13>I34,1-I18,0),0) -> 0.9715597 | J46: =IFERROR(IF(J13>J34,1-J18,0),0) -> 0.98830222 | K46: =IFERROR(IF(K13>K34,1-K18,0),0) -> 0.98895959

Sheet Quarters
A1: ='Profit & Loss'!A1 -> AXIS BANK LTD | E1: =UPDATE | J1: SCREENER.IN
A3: Narration | B3: ='Data Sheet'!B41 -> 45107 | C3: ='Data Sheet'!C41 -> 45199 | D3: ='Data Sheet'!D41 -> 45291 | E3: ='Data Sheet'!E41 -> 45382 | F3: ='Data Sheet'!F41 -> 45473 | G3: ='Data Sheet'!G41 -> 45565 | H3: ='Data Sheet'!H41 -> 45657 | I3: ='Data Sheet'!I41 -> 45747 | ... K3: ='Data Sheet'!K41 -> 45930
A4: Sales | B4: ='Data Sheet'!B42 -> 26245.74 | C4: ='Data Sheet'!C42 -> 27417.53 | D4: ='Data Sheet'!D42 -> 28865.2 | E4: ='Data Sheet'!E42 -> 30230.58 | F4: ='Data Sheet'!F42 -> 31158.52 | G4: ='Data Sheet'!G42 -> 31601.05 | H4: ='Data Sheet'!H42 -> 32162.2 | I4: ='Data Sheet'!I42 -> 32452.32 | ... K4: ='Data Sheet'!K42 -> 32309.77
A5: Expenses | B5: ='Data Sheet'!B43 -> 9730.68 | C5: ='Data Sheet'!C43 -> 10059.45 | D5: ='Data Sheet'!D43 -> 10506.5 | E5: ='Data Sheet'!E43 -> 11123.99 | F5: ='Data Sheet'!F43 -> 11891.54 | G5: ='Data Sheet'!G43 -> 12411.56 | H5: ='Data Sheet'!H43 -> 11912.73 | I5: ='Data Sheet'!I43 -> 11942.56 | ... K5: ='Data Sheet'!K43 -> 14302.44
A6: Operating Profit | B6: ='Data Sheet'!B50 -> 16515.06 | C6: ='Data Sheet'!C50 -> 17358.08 | D6: ='Data Sheet'!D50 -> 18358.7 | E6: ='Data Sheet'!E50 -> 19106.59 | F6: ='Data Sheet'!F50 -> 19266.98 | G6: ='Data Sheet'!G50 -> 19189.49 | H6: ='Data Sheet'!H50 -> 20249.47 | I6: ='Data Sheet'!I50 -> 20509.76 | ... K6: ='Data Sheet'!K50 -> 18007.33
A7: Other Income | B7: ='Data Sheet'!B44 -> 5648.46 | C7: ='Data Sheet'!C44 -> 5704.7 | D7: ='Data Sheet'!D44 -> 6271.63 | E7: ='Data Sheet'!E44 -> 7605.52 | F7: ='Data Sheet'!F44 -> 6637.36 | G7: ='Data Sheet'!G44 -> 7602.72 | H7: ='Data Sheet'!H44 -> 6796.97 | I7: ='Data Sheet'!I44 -> 7505.72 | ... K7: ='Data Sheet'!K44 -> 7460.08
A8: Depreciation | B8: ='Data Sheet'!B45 -> 0 | C8: ='Data Sheet'!C45 -> 0 | D8: ='Data Sheet'!D45 -> 0 | E8: ='Data Sheet'!E45 -> 0 | F8: ='Data Sheet'!F45 -> 0 | G8: ='Data Sheet'!G45 -> 0 | H8: ='Data Sheet'!H45 -> 0 | I8: ='Data Sheet'!I45 -> 0 | ... K8: ='Data Sheet'!K45 -> 0
A9: Interest | B9: ='Data Sheet'!B46 -> 13971.9 | C9: ='Data Sheet'!C46 -> 14748.97 | D9: ='Data Sheet'!D46 -> 15942.63 | E9: ='Data Sheet'!E46 -> 16727.24 | F9: ='Data Sheet'!F46 -> 17261 | G9: ='Data Sheet'!G46 -> 17614.92 | H9: ='Data Sheet'!H46 -> 18039.68 | I9: ='Data Sheet'!I46 -> 18120.71 | ... K9: ='Data Sheet'!K46 -> 17971.47
A10: Profit before tax | B10: ='Data Sheet'!B47 -> 8191.62 | C10: ='Data Sheet'!C47 -> 8313.81 | D10: ='Data Sheet'!D47 -> 8687.7 | E10: ='Data Sheet'!E47 -> 9984.87 | F10: ='Data Sheet'!F47 -> 8643.34 | G10: ='Data Sheet'!G47 -> 9177.29 | H10: ='Data Sheet'!H47 -> 9006.76 | I10: ='Data Sheet'!I47 -> 9894.77 | ... K10: ='Data Sheet'!K47 -> 7495.94
A11: Tax | B11: ='Data Sheet'!B48 -> 2092.67 | C11: ='Data Sheet'!C48 -> 2096.13 | D11: ='Data Sheet'!D48 -> 2194.34 | E11: ='Data Sheet'!E48 -> 2371.32 | F11: ='Data Sheet'!F48 -> 2193.31 | G11: ='Data Sheet'!G48 -> 1768.39 | H11: ='Data Sheet'!H48 -> 2243.66 | I11: ='Data Sheet'!I48 -> 2405.06 | ... K11: ='Data Sheet'!K48 -> 1938.43
A12: Net profit | B12: ='Data Sheet'!B49 -> 6091.35 | C12: ='Data Sheet'!C49 -> 6204.15 | D12: ='Data Sheet'!D49 -> 6491.66 | E12: ='Data Sheet'!E49 -> 7599.04 | F12: ='Data Sheet'!F49 -> 6436.43 | G12: ='Data Sheet'!G49 -> 7401.26 | H12: ='Data Sheet'!H49 -> 6742.29 | I12: ='Data Sheet'!I49 -> 7475.13 | ... K12: ='Data Sheet'!K49 -> 5527.85
A14: OPM | B14: =IF(B4>0,B6/B4,"") -> 0.62924726 | C14: =IF(C4>0,C6/C4,"") -> 0.63310152 | D14: =IF(D4>0,D6/D4,"") -> 0.63601499 | E14: =IF(E4>0,E6/E4,"") -> 0.63202856 | F14: =IF(F4>0,F6/F4,"") -> 0.6183535 | G14: =IF(G4>0,G6/G4,"") -> 0.60724216 | H14: =IF(H4>0,H6/H4,"") -> 0.62960463 | I14: =IF(I4>0,I6/I4,"") -> 0.63199673 | ... K14: =IF(K4>0,K6/K4,"") -> 0.5573339

Sheet Balance Sheet
A1: ='Profit & Loss'!A1 -> AXIS BANK LTD | E1: =UPDATE | J1: SCREENER.IN
A3: Narration | B3: ='Data Sheet'!B56 -> 42460 | C3: ='Data Sheet'!C56 -> 42825 | D3: ='Data Sheet'!D56 -> 43190 | E3: ='Data Sheet'!E56 -> 43555 | F3: ='Data Sheet'!F56 -> 43921 | G3: ='Data Sheet'!G56 -> 44286 | H3: ='Data Sheet'!H56 -> 44651 | I3: ='Data Sheet'!I56 -> 45016 | ... K3: ='Data Sheet'!K56 -> 45747
A4: Equity Share Capital | B4: ='Data Sheet'!B57 -> 476.57 | C4: ='Data Sheet'!C57 -> 479.01 | D4: ='Data Sheet'!D57 -> 513.31 | E4: ='Data Sheet'!E57 -> 514.33 | F4: ='Data Sheet'!F57 -> 564.34 | G4: ='Data Sheet'!G57 -> 612.75 | H4: ='Data Sheet'!H57 -> 613.95 | I4: ='Data Sheet'!I57 -> 615.37 | ... K4: ='Data Sheet'!K57 -> 619.47
A5: Reserves | B5: ='Data Sheet'!B58 -> 53082.19 | C5: ='Data Sheet'!C58 -> 55901.34 | D5: ='Data Sheet'!D58 -> 63694.1 | E5: ='Data Sheet'!E58 -> 67288.29 | F5: ='Data Sheet'!F58 -> 85776.09 | G5: ='Data Sheet'!G58 -> 102980.95 | H5: ='Data Sheet'!H58 -> 117646.71 | I5: ='Data Sheet'!I58 -> 129166.34 | ... K5: ='Data Sheet'!K58 -> 186616.02
A6: Borrowings | B6: ='Data Sheet'!B59 -> 472149.92 | C6: ='Data Sheet'!C59 -> 527437.44 | D6: ='Data Sheet'!D59 -> 611424.85 | E6: ='Data Sheet'!E59 -> 711995.77 | F6: ='Data Sheet'!F59 -> 797337.38 | G6: ='Data Sheet'!G59 -> 850551.35 | H6: ='Data Sheet'!H59 -> 1020943 | I6: ='Data Sheet'!I59 -> 1152038.3 | ... K6: ='Data Sheet'!K59 -> 1391607.6
A7: Other Liabilities | B7: ='Data Sheet'!B60 -> 20677.94 | C7: ='Data Sheet'!C60 -> 27644.22 | D7: ='Data Sheet'!D60 -> 28071.11 | E7: ='Data Sheet'!E60 -> 34247.58 | F7: ='Data Sheet'!F60 -> 44194 | G7: ='Data Sheet'!G60 -> 46859.49 | H7: ='Data Sheet'!H60 -> 56575.53 | I7: ='Data Sheet'!I60 -> 62597.96 | ... K7: ='Data Sheet'!K60 -> 78119.48
A8: Total | B8: ='Data Sheet'!B61 -> 546386.62 | C8: ='Data Sheet'!C61 -> 611462.01 | D8: ='Data Sheet'!D61 -> 703703.37 | E8: ='Data Sheet'!E61 -> 814045.97 | F8: ='Data Sheet'!F61 -> 927871.81 | G8: ='Data Sheet'!G61 -> 1001004.5 | H8: ='Data Sheet'!H61 -> 1195779.1 | I8: ='Data Sheet'!I61 -> 1344418 | ... K8: ='Data Sheet'!K61 -> 1656962.6
A10: Net Block | B10: ='Data Sheet'!B62 -> 3357.87 | C10: ='Data Sheet'!C62 -> 3518.14 | D10: ='Data Sheet'!D62 -> 3697.03 | E10: ='Data Sheet'!E62 -> 3842.12 | F10: ='Data Sheet'!F62 -> 3911.74 | G10: ='Data Sheet'!G62 -> 4500.59 | H10: ='Data Sheet'!H62 -> 4753.23 | I10: ='Data Sheet'!I62 -> 4999.68 | ... K10: ='Data Sheet'!K62 -> 6660.74
A11: Capital Work in Progress | B11: ='Data Sheet'!B63 -> 215.89 | C11: ='Data Sheet'!C63 -> 292.1 | D11: ='Data Sheet'!D63 -> 351.79 | E11: ='Data Sheet'!E63 -> 287.76 | F11: ='Data Sheet'!F63 -> 482.6 | G11: ='Data Sheet'!G63 -> 118.34 | H11: ='Data Sheet'!H63 -> 215.13 | I11: ='Data Sheet'!I63 -> 142.14 | ... K11: ='Data Sheet'!K63 -> 120.58
A12: Investments | B12: ='Data Sheet'!B64 -> 131398.64 | C12: ='Data Sheet'!C64 -> 129018.35 | D12: ='Data Sheet'!D64 -> 153036.71 | E12: ='Data Sheet'!E64 -> 174055.85 | F12: ='Data Sheet'!F64 -> 155281.63 | G12: ='Data Sheet'!G64 -> 225335.77 | H12: ='Data Sheet'!H64 -> 274608.13 | I12: ='Data Sheet'!I64 -> 288094.83 | ... K12: ='Data Sheet'!K64 -> 396685.07
A13: Other Assets | B13: ='Data Sheet'!B65 -> 411414.22 | C13: ='Data Sheet'!C65 -> 478633.42 | D13: ='Data Sheet'!D65 -> 546617.84 | E13: ='Data Sheet'!E65 -> 635860.24 | F13: ='Data Sheet'!F65 -> 768195.84 | G13: ='Data Sheet'!G65 -> 771049.84 | H13: ='Data Sheet'!H65 -> 916202.66 | I13: ='Data Sheet'!I65 -> 1051181.3 | ... K13: ='Data Sheet'!K65 -> 1253496.2
A14: Total | B14: ='Data Sheet'!B66 -> 546386.62 | C14: ='Data Sheet'!C66 -> 611462.01 | D14: ='Data Sheet'!D66 -> 703703.37 | E14: ='Data Sheet'!E66 -> 814045.97 | F14: ='Data Sheet'!F66 -> 927871.81 | G14: ='Data Sheet'!G66 -> 1001004.5 | H14: ='Data Sheet'!H66 -> 1195779.1 | I14: ='Data Sheet'!I66 -> 1344418 | ... K14: ='Data Sheet'!K66 -> 1656962.6
A16: Working Capital | B16: =B13-B7 -> 390736.28 | C16: =C13-C7 -> 450989.2 | D16: =D13-D7 -> 518546.73 | E16: =E13-E7 -> 601612.66 | F16: =F13-F7 -> 724001.84 | G16: =G13-G7 -> 724190.35 | H16: =H13-H7 -> 859627.13 | I16: =I13-I7 -> 988583.35 | ... K16: =K13-K7 -> 1175376.7
A17: Debtors | B17: ='Data Sheet'!B67 -> 0 | C17: ='Data Sheet'!C67 -> 0 | D17: ='Data Sheet'!D67 -> 0 | E17: ='Data Sheet'!E67 -> 0 | F17: ='Data Sheet'!F67 -> 0 | G17: ='Data Sheet'!G67 -> 0 | H17: ='Data Sheet'!H67 -> 0 | I17: ='Data Sheet'!I67 -> 0 | ... K17: ='Data Sheet'!K67 -> 0
A18: Inventory | B18: ='Data Sheet'!B68 -> 0 | C18: ='Data Sheet'!C68 -> 0 | D18: ='Data Sheet'!D68 -> 0 | E18: ='Data Sheet'!E68 -> 0 | F18: ='Data Sheet'!F68 -> 0 | G18: ='Data Sheet'!G68 -> 0 | H18: ='Data Sheet'!H68 -> 0 | I18: ='Data Sheet'!I68 -> 0 | ... K18: ='Data Sheet'!K68 -> 0
A20: Debtor Days | B20: =IF('Profit & Loss'!B4>0,'Balance Sheet'!B17/('Profit & Loss'!B4/365),0) -> 0 | C20: =IF('Profit & Loss'!C4>0,'Balance Sheet'!C17/('Profit & Loss'!C4/365),0) -> 0 | D20: =IF('Profit & Loss'!D4>0,'Balance Sheet'!D17/('Profit & Loss'!D4/365),0) -> 0 | E20: =IF('Profit & Loss'!E4>0,'Balance Sheet'!E17/('Profit & Loss'!E4/365),0) -> 0 | F20: =IF('Profit & Loss'!F4>0,'Balance Sheet'!F17/('Profit & Loss'!F4/365),0) -> 0 | G20: =IF('Profit & Loss'!G4>0,'Balance Sheet'!G17/('Profit & Loss'!G4/365),0) -> 0 | H20: =IF('Profit & Loss'!H4>0,'Balance Sheet'!H17/('Profit & Loss'!H4/365),0) -> 0 | I20: =IF('Profit & Loss'!I4>0,'Balance Sheet'!I17/('Profit & Loss'!I4/365),0) -> 0 | ... K20: =IF('Profit & Loss'!K4>0,'Balance Sheet'!K17/('Profit & Loss'!K4/365),0) -> 0
A21: Inventory Turnover | B21: =IF('Balance Sheet'!B18>0,'Profit & Loss'!B4/'Balance Sheet'!B18,0) -> 0 | C21: =IF('Balance Sheet'!C18>0,'Profit & Loss'!C4/'Balance Sheet'!C18,0) -> 0 | D21: =IF('Balance Sheet'!D18>0,'Profit & Loss'!D4/'Balance Sheet'!D18,0) -> 0 | E21: =IF('Balance Sheet'!E18>0,'Profit & Loss'!E4/'Balance Sheet'!E18,0) -> 0 | F21: =IF('Balance Sheet'!F18>0,'Profit & Loss'!F4/'Balance Sheet'!F18,0) -> 0 | G21: =IF('Balance Sheet'!G18>0,'Profit & Loss'!G4/'Balance Sheet'!G18,0) -> 0 | H21: =IF('Balance Sheet'!H18>0,'Profit & Loss'!H4/'Balance Sheet'!H18,0) -> 0 | I21: =IF('Balance Sheet'!I18>0,'Profit & Loss'!I4/'Balance Sheet'!I18,0) -> 0 | ... K21: =IF('Balance Sheet'!K18>0,'Profit & Loss'!K4/'Balance Sheet'!K18,0) -> 0
A23: Return on Equity | B23: =IF(SUM('Balance Sheet'!B4:B5)>0,'Profit & Loss'!B12/SUM('Balance Sheet'!B4:B5),"") -> 0.15589737 | C23: =IF(SUM('Balance Sheet'!C4:C5)>0,'Profit & Loss'!C12/SUM('Balance Sheet'!C4:C5),"") -> 0.070113612 | D23: =IF(SUM('Balance Sheet'!D4:D5)>0,'Profit & Loss'!D12/SUM('Balance Sheet'!D4:D5),"") -> 0.0070991806 | E23: =IF(SUM('Balance Sheet'!E4:E5)>0,'Profit & Loss'!E12/SUM('Balance Sheet'!E4:E5),"") -> 0.074312615 | F23: =IF(SUM('Balance Sheet'!F4:F5)>0,'Profit & Loss'!F12/SUM('Balance Sheet'!F4:F5),"") -> 0.02146283 | G23: =IF(SUM('Balance Sheet'!G4:G5)>0,'Profit & Loss'!G12/SUM('Balance Sheet'!G4:G5),"") -> 0.069458857 | H23: =IF(SUM('Balance Sheet'!H4:H5)>0,'Profit & Loss'!H12/SUM('Balance Sheet'!H4:H5),"") -> 0.11939127 | I23: =IF(SUM('Balance Sheet'!I4:I5)>0,'Profit & Loss'!I12/SUM('Balance Sheet'!I4:I5),"") -> 0.083358818 | ... K23: =IF(SUM('Balance Sheet'!K4:K5)>0,'Profit & Loss'!K12/SUM('Balance Sheet'!K4:K5),"") -> 0.14983863
A24: Return on Capital Emp | C24: =IF((B4+B5+B6+C4+C5+C6)>0,('Profit & Loss'!C10+'Profit & Loss'!C9)*2/(B4+B5+B6+C4+C5+C6),"") -> 0.059021864 | D24: =IF((C4+C5+C6+D4+D5+D6)>0,('Profit & Loss'!D10+'Profit & Loss'!D9)*2/(C4+C5+C6+D4+D5+D6),"") -> 0.044733128 | E24: =IF((D4+D5+D6+E4+E5+E6)>0,('Profit & Loss'!E10+'Profit & Loss'!E9)*2/(D4+D5+D6+E4+E5+E6),"") -> 0.056994155 | F24: =IF((E4+E5+E6+F4+F5+F6)>0,('Profit & Loss'!F10+'Profit & Loss'!F9)*2/(E4+E5+E6+F4+F5+F6),"") -> 0.052030789 | G24: =IF((F4+F5+F6+G4+G5+G6)>0,('Profit & Loss'!G10+'Profit & Loss'!G9)*2/(F4+F5+F6+G4+G5+G6),"") -> 0.048293512 | H24: =IF((G4+G5+G6+H4+H5+H6)>0,('Profit & Loss'!H10+'Profit & Loss'!H9)*2/(G4+G5+G6+H4+H5+H6),"") -> 0.051450693 | I24: =IF((H4+H5+H6+I4+I5+I6)>0,('Profit & Loss'!I10+'Profit & Loss'!I9)*2/(H4+H5+H6+I4+I5+I6),"") -> 0.051226539 | J24: =IF((I4+I5+I6+J4+J5+J6)>0,('Profit & Loss'!J10+'Profit & Loss'!J9)*2/(I4+I5+I6+J4+J5+J6),"") -> 0.070639065 | K24: =IF((J4+J5+J6+K4+K5+K6)>0,('Profit & Loss'!K10+'Profit & Loss'!K9)*2/(J4+J5+J6+K4+K5+K6),"") -> 0.071100281
A26: BOOK VALUE | B26: =B4+B5 -> 53558.76 | C26: =C4+C5 -> 56380.35 | D26: =D4+D5 -> 64207.41 | E26: =E4+E5 -> 67802.62 | F26: =F4+F5 -> 86340.43 | G26: =G4+G5 -> 103593.7 | H26: =H4+H5 -> 118260.66 | I26: =I4+I5 -> 129781.71 | ... K26: =K4+K5 -> 187235.49

Sheet Cash Flow
A1: ='Balance Sheet'!A1 -> AXIS BANK LTD | E1: =UPDATE | J1: SCREENER.IN
A3: Narration | B3: ='Data Sheet'!B81 -> 42460 | C3: ='Data Sheet'!C81 -> 42825 | D3: ='Data Sheet'!D81 -> 43190 | E3: ='Data Sheet'!E81 -> 43555 | F3: ='Data Sheet'!F81 -> 43921 | G3: ='Data Sheet'!G81 -> 44286 | H3: ='Data Sheet'!H81 -> 44651 | I3: ='Data Sheet'!I81 -> 45016 | ... K3: ='Data Sheet'!K81 -> 45747
A4: Cash from Operating Activity | B4: ='Data Sheet'!B82 -> -34494.68 | C4: ='Data Sheet'!C82 -> 32208.62 | D4: ='Data Sheet'!D82 -> -38390.3 | E4: ='Data Sheet'!E82 -> 37125.25 | F4: ='Data Sheet'!F82 -> 30415.64 | G4: ='Data Sheet'!G82 -> 12632.88 | H4: ='Data Sheet'!H82 -> 28137.3 | I4: ='Data Sheet'!I82 -> 22074.78 | ... K4: ='Data Sheet'!K82 -> 44383.68
A5: Cash from Investing Activity | B5: ='Data Sheet'!B83 -> 9210.7 | C5: ='Data Sheet'!C83 -> -12458.4 | D5: ='Data Sheet'!D83 -> -10007.1 | E5: ='Data Sheet'!E83 -> -18674.35 | F5: ='Data Sheet'!F83 -> -9485.3 | G5: ='Data Sheet'!G83 -> -54287.63 | H5: ='Data Sheet'!H83 -> -27112.23 | I5: ='Data Sheet'!I83 -> -32350.9 | ... K5: ='Data Sheet'!K83 -> -51177.8
A6: Cash from Financing Activity | B6: ='Data Sheet'!B84 -> 22494.69 | C6: ='Data Sheet'!C84 -> -2486.91 | D6: ='Data Sheet'!D84 -> 41342.09 | E6: ='Data Sheet'!E84 -> 5642.6 | F6: ='Data Sheet'!F84 -> 8865.13 | G6: ='Data Sheet'!G84 -> 7279.33 | H6: ='Data Sheet'!H84 -> 47894.08 | I6: ='Data Sheet'!I84 -> 6640.54 | ... K6: ='Data Sheet'!K84 -> -7000.36
A7: Net Cash Flow | B7: ='Data Sheet'!B85 -> -2789.29 | C7: ='Data Sheet'!C85 -> 17263.31 | D7: ='Data Sheet'!D85 -> -7055.3 | E7: ='Data Sheet'!E85 -> 24093.5 | F7: ='Data Sheet'!F85 -> 29795.47 | G7: ='Data Sheet'!G85 -> -34375.42 | H7: ='Data Sheet'!H85 -> 48919.15 | I7: ='Data Sheet'!I85 -> -3635.58 | ... K7: ='Data Sheet'!K85 -> -13794.48

Sheet Data Sheet
A1: COMPANY NAME | B1: AXIS BANK LTD | E1: =IF(B2<>B3, "A NEW VERSION OF THE WORKSHEET IS AVAILABLE", "")
A2: LATEST VERSION | B2: 2.1 | E2: PLEASE DO NOT MAKE ANY CHANGES TO THIS SHEET
A3: CURRENT VERSION | B3: 2.1
A5: META
A6: Number of shares | B6: =IF(B9>0, B9/B8, 0) -> 312.26
A7: Face Value | B7: 2
A8: Current Price | B8: 1226
A9: Market Capitalization | B9: 382830.76
A15: PROFIT & LOSS
A16: Report Date | B16: 42460 | C16: 42825 | D16: 43190 | E16: 43555 | F16: 43921 | G16: 44286 | H16: 44651 | I16: 45016 | J16: 45382 | K16: 45747
A17: Sales | B17: 41409.25 | C17: 45175.09 | D17: 46614.06 | E17: 56043.65 | F17: 63715.68 | G17: 64397.36 | H17: 68846.06 | I17: 87448.37 | J17: 112759.05 | K17: 127374.09
A18: Raw Material Cost
A19: Change in Inventory
A20: Power and Fuel
A21: Other Mfr. Exp | B21: 736.13 | C21: 880.53 | D21: 878.06 | E21: 1093.22 | F21: 1186.04 | G21: 1245.68 | H21: 1449.92 | I21: 1595.42 | J21: 1939.23 | K21: 2329.69
A22: Employee Cost | B22: 4022.38 | C22: 4745.48 | D22: 5417.98 | E22: 5994.16 | F22: 5823.4 | G22: 6773.03 | H22: 8421.24 | I22: 9675.03 | J22: 12204.98 | K22: 13673.12
A23: Selling and admin | B23: 1640.09 | C23: 2126.47 | D23: 2354.92 | E23: 2483.83 | F23: 2640.63 | G23: 2945.93 | H23: 3581.14 | I23: 4022.69 | J23: 4618.48 | K23: 5122.18
A24: Other Expenses | B24: 7470.05 | C24: 16574.38 | D24: 21065.57 | E24: 18448.5 | F24: 26325.54 | G24: 21656.35 | H24: 17764.18 | I24: 15348.18 | J24: 21272.96 | K24: 25269.92
A25: Other Income | B25: 9954.98 | C25: 12421.6 | D25: 11862.62 | E25: 14188.75 | F25: 16341.99 | G25: 13576.92 | H25: 17268.13 | I25: 18348.93 | J25: 25230.31 | K25: 28542.77
A26: Depreciation | B26: 461.39 | C26: 526.67 | D26: 590.58 | E26: 737.17 | F26: 806.07 | G26: 975.83 | H26: 1045.59 | I26: 13145.65 | J26: 1384.97 | K26: 1763.48
A27: Interest | B27: 24344.23 | C27: 26789.35 | D27: 27603.69 | E27: 33883.47 | F27: 37995.94 | G27: 34627.38 | H27: 34922.66 | I27: 43389.15 | J27: 61390.74 | K27: 71036.31
A28: Profit before tax | B28: 12689.96 | C28: 5953.81 | D28: 565.88 | E28: 7592.05 | F28: 5280.05 | G28: 9750.08 | H28: 18929.46 | I28: 18621.18 | J28: 35178 | K28: 36722.16
A29: Tax | B29: 4332.38 | C29: 1986.78 | D29: 101.86 | E29: 2544.96 | F29: 3401.29 | G29: 2497.69 | H29: 4765.11 | I29: 7768.52 | J29: 8754.46 | K29: 8610.42
A30: Net profit | B30: 8349.67 | C30: 3953.03 | D30: 455.82 | E30: 5038.59 | F30: 1853.11 | G30: 7195.5 | H30: 14119.29 | I30: 10818.45 | J30: 26386.2 | K30: 28055.11
A31: Dividend Amount | B31: 1191.42 | C31: 1197.52 | E31: 257.16 | H31: 306.98 | I31: 307.68 | J31: 308.66 | K31: 309.74
A40: Quarters
A41: Report Date | B41: 45107 | C41: 45199 | D41: 45291 | E41: 45382 | F41: 45473 | G41: 45565 | H41: 45657 | I41: 45747 | J41: 45838 | K41: 45930
A42: Sales | B42: 26245.74 | C42: 27417.53 | D42: 28865.2 | E42: 30230.58 | F42: 31158.52 | G42: 31601.05 | H42: 32162.2 | I42: 32452.32 | J42: 32348.31 | K42: 32309.77
A43: Expenses | B43: 9730.68 | C43: 10059.45 | D43: 10506.5 | E43: 11123.99 | F43: 11891.54 | G43: 12411.56 | H43: 11912.73 | I43: 11942.56 | J43: 13982.61 | K43: 14302.44
A44: Other Income | B44: 5648.46 | C44: 5704.7 | D44: 6271.63 | E44: 7605.52 | F44: 6637.36 | G44: 7602.72 | H44: 6796.97 | I44: 7505.72 | J44: 8052.69 | K44: 7460.08
A45: Depreciation
A46: Interest | B46: 13971.9 | C46: 14748.97 | D46: 15942.63 | E46: 16727.24 | F46: 17261 | G46: 17614.92 | H46: 18039.68 | I46: 18120.71 | J46: 18238.69 | K46: 17971.47
A47: Profit before tax | B47: 8191.62 | C47: 8313.81 | D47: 8687.7 | E47: 9984.87 | F47: 8643.34 | G47: 9177.29 | H47: 9006.76 | I47: 9894.77 | J47: 8179.7 | K47: 7495.94
A48: Tax | B48: 2092.67 | C48: 2096.13 | D48: 2194.34 | E48: 2371.32 | F48: 2193.31 | G48: 1768.39 | H48: 2243.66 | I48: 2405.06 | J48: 1919.53 | K48: 1938.43
A49: Net profit | B49: 6091.35 | C49: 6204.15 | D49: 6491.66 | E49: 7599.04 | F49: 6436.43 | G49: 7401.26 | H49: 6742.29 | I49: 7475.13 | J49: 6243.72 | K49: 5527.85
A50: Operating Profit | B50: 16515.06 | C50: 17358.08 | D50: 18358.7 | E50: 19106.59 | F50: 19266.98 | G50: 19189.49 | H50: 20249.47 | I50: 20509.76 | J50: 18365.7 | K50: 18007.33
A55: BALANCE SHEET
A56: Report Date | B56: 42460 | C56: 42825 | D56: 43190 | E56: 43555 | F56: 43921 | G56: 44286 | H56: 44651 | I56: 45016 | J56: 45382 | K56: 45747
A57: Equity Share Capital | B57: 476.57 | C57: 479.01 | D57: 513.31 | E57: 514.33 | F57: 564.34 | G57: 612.75 | H57: 613.95 | I57: 615.37 | J57: 617.31 | K57: 619.47 | M57: =F65-F60 -> 724001.84
A58: Reserves | B58: 53082.19 | C58: 55901.34 | D58: 63694.1 | E58: 67288.29 | F58: 85776.09 | G58: 102980.95 | H58: 117646.71 | I58: 129166.34 | J58: 156406.21 | K58: 186616.02
...
